<robot
  name="arm_reference_filtered">
  <link
    name="base_to_rover">
    <inertial>
      <origin
        xyz="0.04 0.0025 -0.06"
        rpy="0 0 0" />
      <mass
        value="0.12926" />
      <inertia
        ixx="0.00015799"
        ixy="9.3247E-24"
        ixz="-2.3244E-21"
        iyy="0.00022782"
        iyz="6.1948E-23"
        izz="7.0371E-05" />
    </inertial>
    <visual>
      <origin
        xyz="0 0 0"
        rpy="0 0 0" />
      <geometry>
        <mesh
          filename="package://arm_reference_filtered/meshes/base_to_rover.stl" />
      </geometry>
      <material
        name="">
        <color
          rgba="0.89804 0.91765 0.92941 1" />
      </material>
    </visual>
    <collision>
      <origin
        xyz="0 0 0"
        rpy="0 0 0" />
      <geometry>
        <mesh
          filename="package://arm_reference_filtered/meshes/base_to_rover.stl" />
      </geometry>
    </collision>
  </link>
  <link
    name="base_link">
    <inertial>
      <origin
        xyz="-0.016925 -0.047257 1.6372E-05"
        rpy="0 0 0" />
      <mass
        value="0.94074" />
      <inertia
        ixx="0.0032103"
        ixy="-0.00052992"
        ixz="1.4658E-07"
        iyy="0.0073743"
        iyz="3.7017E-07"
        izz="0.0074499" />
    </inertial>
    <visual>
      <origin
        xyz="0 0 0"
        rpy="0 0 0" />
      <geometry>
        <mesh
          filename="package://arm_reference_filtered/meshes/base_link.stl" />
      </geometry>
      <material
        name="">
        <color
          rgba="0.89804 0.91765 0.92941 1" />
      </material>
    </visual>
    <collision>
      <origin
        xyz="0 0 0"
        rpy="0 0 0" />
      <geometry>
        <mesh
          filename="package://arm_reference_filtered/meshes/base_link.stl" />
      </geometry>
    </collision>
  </link>
  <joint
    name="base_joint"
    type="continuous">
    <origin
      xyz="0.04 0.06 0.0051"
      rpy="-1.5708 -6.123E-17 -1.5708" />
    <parent
      link="base_to_rover" />
    <child
      link="base_link" />
    <axis
      xyz="0 -1 0" />
  </joint>
  <link
    name="shoulder_link">
    <inertial>
      <origin
        xyz="0.25465 0.0033553 1.7347E-16"
        rpy="0 0 0" />
      <mass
        value="0.21923" />
      <inertia
        ixx="0.00043865"
        ixy="-7.4422E-05"
        ixz="-1.288E-18"
        iyy="0.0053043"
        iyz="1.0708E-18"
        izz="0.0050053" />
    </inertial>
    <visual>
      <origin
        xyz="0 0 0"
        rpy="0 0 0" />
      <geometry>
        <mesh
          filename="package://arm_reference_filtered/meshes/shoulder_link.stl" />
      </geometry>
      <material
        name="">
        <color
          rgba="0.79216 0.81961 0.93333 1" />
      </material>
    </visual>
    <collision>
      <origin
        xyz="0 0 0"
        rpy="0 0 0" />
      <geometry>
        <mesh
          filename="package://arm_reference_filtered/meshes/shoulder_link.stl" />
      </geometry>
    </collision>
  </link>
  <joint
    name="shoulder_joint"
    type="continuous">
    <origin
      xyz="0.078833 -0.035 0"
      rpy="3.1416 0 -0.87998" />
    <parent
      link="base_link" />
    <child
      link="shoulder_link" />
    <axis
      xyz="0 0 -1" />
  </joint>
  <link
    name="elbow_link">
    <inertial>
      <origin
        xyz="0.16877 0.0033689 -5.1972E-15"
        rpy="0 0 0" />
      <mass
        value="0.36052" />
      <inertia
        ixx="0.00056775"
        ixy="8.4831E-05"
        ixz="-1.8064E-18"
        iyy="0.0048212"
        iyz="5.7786E-20"
        izz="0.0044009" />
    </inertial>
    <visual>
      <origin
        xyz="0 0 0"
        rpy="0 0 0" />
      <geometry>
        <mesh
          filename="package://arm_reference_filtered/meshes/elbow_link.stl" />
      </geometry>
      <material
        name="">
        <color
          rgba="0.89804 0.91765 0.92941 1" />
      </material>
    </visual>
    <collision>
      <origin
        xyz="0 0 0"
        rpy="0 0 0" />
      <geometry>
        <mesh
          filename="package://arm_reference_filtered/meshes/elbow_link.stl" />
      </geometry>
    </collision>
  </link>
  <joint
    name="elbow_joint"
    type="continuous">
    <origin
      xyz="0.5 0 0"
      rpy="0 6.9389E-16 -1.3124" />
    <parent
      link="shoulder_link" />
    <child
      link="elbow_link" />
    <axis
      xyz="0 0 -1" />
  </joint>
  <link
    name="rest_link">
    <inertial>
      <origin
        xyz="0.034923 -0.0067291 -1.9686E-05"
        rpy="0 0 0" />
      <mass
        value="0.20024" />
      <inertia
        ixx="0.00038951"
        ixy="1.1108E-05"
        ixz="-3.2693E-08"
        iyy="0.00033012"
        iyz="-2.4354E-08"
        izz="0.00039361" />
    </inertial>
    <visual>
      <origin
        xyz="0 0 0"
        rpy="0 0 0" />
      <geometry>
        <mesh
          filename="package://arm_reference_filtered/meshes/rest_link.stl" />
      </geometry>
      <material
        name="">
        <color
          rgba="0.89804 0.91765 0.92941 1" />
      </material>
    </visual>
    <collision>
      <origin
        xyz="0 0 0"
        rpy="0 0 0" />
      <geometry>
        <mesh
          filename="package://arm_reference_filtered/meshes/rest_link.stl" />
      </geometry>
    </collision>
  </link>
  <joint
    name="rest_joint"
    type="continuous">
    <origin
      xyz="0.35 0 0"
      rpy="-3.1416 8.2509E-17 0.49263" />
    <parent
      link="elbow_link" />
    <child
      link="rest_link" />
    <axis
      xyz="0 0 1" />
  </joint>
  <link
    name="twist_link">
    <inertial>
      <origin
        xyz="-0.052487 0.002038 8.8203E-05"
        rpy="0 0 0" />
      <mass
        value="0.30581" />
      <inertia
        ixx="0.0003103"
        ixy="-9.332E-07"
        ixz="2.0573E-07"
        iyy="0.000347"
        iyz="1.6219E-07"
        izz="0.00036455" />
    </inertial>
    <visual>
      <origin
        xyz="0 0 0"
        rpy="0 0 0" />
      <geometry>
        <mesh
          filename="package://arm_reference_filtered/meshes/twist_link.stl" />
      </geometry>
      <material
        name="">
        <color
          rgba="0.89804 0.91765 0.92941 1" />
      </material>
    </visual>
    <collision>
      <origin
        xyz="0 0 0"
        rpy="0 0 0" />
      <geometry>
        <mesh
          filename="package://arm_reference_filtered/meshes/twist_link.stl" />
      </geometry>
    </collision>
  </link>
  <joint
    name="twist_joint"
    type="continuous">
    <origin
      xyz="0.08 0 0"
      rpy="-3.1416 -0.050003 3.1416" />
    <parent
      link="rest_link" />
    <child
      link="twist_link" />
    <axis
      xyz="0 -1 0" />
  </joint>
  <link
    name="gripper_link">
    <inertial>
      <origin
        xyz="1.7576E-05 0.020833 3.0442E-05"
        rpy="0 0 0" />
      <mass
        value="0.11209" />
      <inertia
        ixx="7.8261E-05"
        ixy="-1.0719E-08"
        ixz="-1.2772E-07"
        iyy="0.00012632"
        iyz="-1.8565E-08"
        izz="7.8113E-05" />
    </inertial>
    <visual>
      <origin
        xyz="0 0 0"
        rpy="0 0 0" />
      <geometry>
        <mesh
          filename="package://arm_reference_filtered/meshes/gripper_link.stl" />
      </geometry>
      <material
        name="">
        <color
          rgba="0.89804 0.91765 0.92941 1" />
      </material>
    </visual>
    <collision>
      <origin
        xyz="0 0 0"
        rpy="0 0 0" />
      <geometry>
        <mesh
          filename="package://arm_reference_filtered/meshes/gripper_link.stl" />
      </geometry>
    </collision>
  </link>
  <joint
    name="gripper_joint"
    type="continuous">
    <origin
      xyz="-0.17704 0.00090857 0.00050796"
      rpy="1.5904E-15 -0.5103 1.5708" />
    <parent
      link="twist_link" />
    <child
      link="gripper_link" />
    <axis
      xyz="0 1 0" />
  </joint>
</robot>