<?xml version="1.0" ?>
<!-- =================================================================================== -->
<!-- |    This document was autogenerated by xacro from robot6.urdf                    | -->
<!-- |    EDITING THIS FILE BY HAND IS NOT RECOMMENDED                                 | -->
<!-- =================================================================================== -->
<!-- =================================================================================== -->
<!-- |    This document was autogenerated by xacro from robot2.xacro                   | -->
<!-- |    EDITING THIS FILE BY HAND IS NOT RECOMMENDED                                 | -->
<!-- =================================================================================== -->
<!-- =================================================================================== -->
<!-- |    This document was autogenerated by xacro from robot2.urdf                    | -->
<!-- |    EDITING THIS FILE BY HAND IS NOT RECOMMENDED                                 | -->
<!-- =================================================================================== -->
<!-- =================================================================================== -->
<!-- |    This document was autogenerated by xacro from diff_wheeled_robot.xacro       | -->
<!-- |    EDITING THIS FILE BY HAND IS NOT RECOMMENDED                                 | -->
<!-- =================================================================================== -->
<robot name="robot1" xmlns:xacro="http://www.ros.org/wiki/xacro">
  <link name="base_link">
    <inertial>
      <origin rpy="0 0 0" xyz="-0.000800600263010614 -0.11860258145137 0.455394457326262"/>
      <mass value="4.27804006349508"/>
      <inertia ixx="0.223279268967413" ixy="-0.000727461158529111" ixz="-3.35208728745676E-06" iyy="0.142337282720164" iyz="6.97566155290899E-05" izz="0.349709434624979"/>
    </inertial>
    <visual>
      <origin rpy="0 0 0" xyz="0 0 0"/>
      <geometry>
        <mesh filename="package://robot1/meshes/base_link.stl"/>
      </geometry>
      <material name="">
        <color rgba="0.898039215686275 0.917647058823529 0.929411764705882 1"/>
      </material>
    </visual>
    <collision>
      <origin rpy="0 0 0" xyz="0 0 0"/>
      <geometry>
        <mesh filename="package://robot1/meshes/base_link.stl"/>
      </geometry>
    </collision>
  </link>
  <gazebo reference="base_link">
    <material>Gazebo/Grey</material>
  </gazebo>
  <link name="bogie_left">
    <inertial>
      <origin rpy="0 0 0" xyz="0.00360195091703333 -0.156872819581089 -0.0770599329146603"/>
      <mass value="1.54434655072793"/>
      <inertia ixx="0.0238244757958653" ixy="0.00118304598138277" ixz="6.87987185265187E-05" iyy="0.0646733940389408" iyz="-0.00141276494033457" izz="0.0874730986459172"/>
    </inertial>
    <visual>
      <origin rpy="0 0 0" xyz="0 0 0"/>
      <geometry>
        <mesh filename="package://robot1/meshes/bogie_left.stl"/>
      </geometry>
      <material name="">
        <color rgba="0.898039215686275 0.917647058823529 0.929411764705882 1"/>
      </material>
    </visual>
    <collision>
      <origin rpy="0 0 0" xyz="0 0 0"/>
      <geometry>
        <mesh filename="package://robot1/meshes/bogie_left.stl"/>
      </geometry>
    </collision>
  </link>
  <joint name="joint_bogie_left" type="revolute">
    <origin rpy="1.5708 0.0053459 1.5708" xyz="-0.176 0.187 0.42252"/>
    <parent link="base_link"/>
    <child link="bogie_left"/>
    <axis xyz="0 0 1"/>
    <limit effort="1000" lower="0.0" upper="0.0" velocity="0.5"/>
  </joint>
  <gazebo reference="bogie_left">
    <material>Gazebo/FlatBlack</material>
  </gazebo>
  <link name="L4">
    <inertial>
      <origin rpy="0 0 0" xyz="-0.0908549897031922 3.60822483003176E-16 -1.88737914186277E-15"/>
      <mass value="9.18939845373489"/>
      <inertia ixx="0.087465651826933" ixy="-4.08851490219851E-18" ixz="1.11550622041014E-17" iyy="0.065169129886498" iyz="-1.73472347597681E-18" izz="0.065169129886498"/>
    </inertial>
    <visual>
      <origin rpy="0 0 0" xyz="0 0 0"/>
      <geometry>
        <mesh filename="package://robot1/meshes/L4.stl"/>
      </geometry>
      <material name="">
        <color rgba="0.901960784313726 0.92156862745098 0.92156862745098 1"/>
      </material>
    </visual>
    <collision>
      <origin rpy="0 0 0" xyz="0 0 0"/>
      <geometry>
        <mesh filename="package://robot1/meshes/L4.stl"/>
      </geometry>
    </collision>
  </link>
  <joint name="JL4" type="continuous">
    <origin rpy="3.1051 -1.5708 0" xyz="0.27464 -0.2922 -0.0935"/>
    <parent link="bogie_left"/>
    <child link="L4"/>
    <axis xyz="1 0 0"/>
  </joint>
  <gazebo reference="L4">
    <material>Gazebo/Gold</material>
    <mu1>0.63</mu1>
    <mu2>0.65</mu2>
  </gazebo>
  <link name="L5">
    <inertial>
      <origin rpy="0 0 0" xyz="-0.0908549897031924 -8.32667268468867E-17 4.02455846426619E-16"/>
      <mass value="9.1893984537349"/>
      <inertia ixx="0.0874656518269331" ixy="1.00230329151726E-17" ixz="-3.70112437785572E-17" iyy="0.0651691298864981" iyz="-3.46944695195361E-18" izz="0.065169129886498"/>
    </inertial>
    <visual>
      <origin rpy="0 0 0" xyz="0 0 0"/>
      <geometry>
        <mesh filename="package://robot1/meshes/L5.stl"/>
      </geometry>
      <material name="">
        <color rgba="0.901960784313726 0.92156862745098 0.92156862745098 1"/>
      </material>
    </visual>
    <collision>
      <origin rpy="0 0 0" xyz="0 0 0"/>
      <geometry>
        <mesh filename="package://robot1/meshes/L5.stl"/>
      </geometry>
    </collision>
  </link>
  <joint name="JL5" type="continuous">
    <origin rpy="2.32070664954404 -1.5707963267949 0" xyz="-0.250000000000006 -0.294999999999997 -0.0934999999999989"/>
    <parent link="bogie_left"/>
    <child link="L5"/>
    <axis xyz="1 0 0"/>
  </joint>
  <gazebo reference="L5">
    <material>Gazebo/Gold</material>
    <mu1>0.63</mu1>
    <mu2>0.65</mu2>
  </gazebo>
  <link name="bogie_right">
    <inertial>
      <origin rpy="0 0 0" xyz="0.00360214216196861 -0.156870111138069 0.0770599329146586"/>
      <mass value="1.54434655072793"/>
      <inertia ixx="0.0238233321963649" ixy="0.00118302614130608" ixz="-6.87926449457258E-05" iyy="0.064674524018448" iyz="0.00141287125414032" izz="0.0874730850259239"/>
    </inertial>
    <visual>
      <origin rpy="0 0 0" xyz="0 0 0"/>
      <geometry>
        <mesh filename="package://robot1/meshes/bogie_right.stl"/>
      </geometry>
      <material name="">
        <color rgba="0.898039215686275 0.917647058823529 0.929411764705882 1"/>
      </material>
    </visual>
    <collision>
      <origin rpy="0 0 0" xyz="0 0 0"/>
      <geometry>
        <mesh filename="package://robot1/meshes/bogie_right.stl"/>
      </geometry>
    </collision>
  </link>
  <joint name="joint_bogie_right" type="revolute">
    <origin rpy="1.5707963267949 0.00534585802001355 1.5707963267949" xyz="0.176000000000001 0.186999999999997 0.422517935490554"/>
    <parent link="base_link"/>
    <child link="bogie_right"/>
    <axis xyz="0 0 1"/>
    <limit effort="1000" lower="0.0" upper="0.0" velocity="0.5"/>
  </joint>
  <gazebo reference="bogie_right">
    <material>Gazebo/FlatBlack</material>
  </gazebo>
  <link name="L1">
    <inertial>
      <origin rpy="0 0 0" xyz="-0.0908549897031924 -5.55111512312578E-17 3.19189119579733E-16"/>
      <mass value="9.1893984537349"/>
      <inertia ixx="0.0874656518269331" ixy="-1.03077238180713E-17" ixz="-1.14137439644496E-17" iyy="0.0651691298864981" iyz="1.73472347597681E-18" izz="0.0651691298864981"/>
    </inertial>
    <visual>
      <origin rpy="0 0 0" xyz="0 0 0"/>
      <geometry>
        <mesh filename="package://robot1/meshes/L1.stl"/>
      </geometry>
      <material name="">
        <color rgba="0.901960784313726 0.92156862745098 0.92156862745098 1"/>
      </material>
    </visual>
    <collision>
      <origin rpy="0 0 0" xyz="0 0 0"/>
      <geometry>
        <mesh filename="package://robot1/meshes/L1.stl"/>
      </geometry>
    </collision>
  </link>
  <joint name="JL1" type="continuous">
    <origin rpy="2.08268339662107 1.5707963267949 0" xyz="0.274642857142856 -0.29219530705668 0.0934999999999976"/>
    <parent link="bogie_right"/>
    <child link="L1"/>
    <axis xyz="-1 0 0"/>
  </joint>
  <gazebo reference="L1">
    <material>Gazebo/Gold</material>
    <mu1>0.63</mu1>
    <mu2>0.65</mu2>
  </gazebo>
  <link name="L2">
    <inertial>
      <origin rpy="0 0 0" xyz="-0.0908549897031922 -1.38777878078145E-16 2.77555756156289E-16"/>
      <mass value="9.1893984537349"/>
      <inertia ixx="0.0874656518269331" ixy="3.62512052091338E-18" ixz="-3.21631798919473E-18" iyy="0.065169129886498" iyz="1.95156391047391E-18" izz="0.0651691298864981"/>
    </inertial>
    <visual>
      <origin rpy="0 0 0" xyz="0 0 0"/>
      <geometry>
        <mesh filename="package://robot1/meshes/L2.stl"/>
      </geometry>
      <material name="">
        <color rgba="0.901960784313726 0.92156862745098 0.92156862745098 1"/>
      </material>
    </visual>
    <collision>
      <origin rpy="0 0 0" xyz="0 0 0"/>
      <geometry>
        <mesh filename="package://robot1/meshes/L2.stl"/>
      </geometry>
    </collision>
  </link>
  <joint name="JL2" type="continuous">
    <origin rpy="3.1002455838996 1.5707963267949 0" xyz="-0.250000000000001 -0.294999999999998 0.0934999999999983"/>
    <parent link="bogie_right"/>
    <child link="L2"/>
    <axis xyz="-1 0 0"/>
  </joint>
  <gazebo reference="L2">
    <material>Gazebo/Gold</material>
    <mu1>0.63</mu1>
    <mu2>0.65</mu2>
  </gazebo>
  <link name="rocker_right">
    <inertial>
      <origin rpy="0 0 0" xyz="-0.160266506545842 3.20657719737882E-06 0.0749142147807074"/>
      <mass value="0.87054039948277"/>
      <inertia ixx="0.000476171150560712" ixy="3.92996260154566E-07" ixz="0.00107017406787956" iyy="0.0173103173691872" iyz="8.50319051005606E-09" izz="0.0171520395788801"/>
    </inertial>
    <visual>
      <origin rpy="0 0 0" xyz="0 0 0"/>
      <geometry>
        <mesh filename="package://robot1/meshes/rocker_right.stl"/>
      </geometry>
      <material name="">
        <color rgba="0.898039215686275 0.917647058823529 0.929411764705882 1"/>
      </material>
    </visual>
    <collision>
      <origin rpy="0 0 0" xyz="0 0 0"/>
      <geometry>
        <mesh filename="package://robot1/meshes/rocker_right.stl"/>
      </geometry>
    </collision>
  </link>
  <joint name="joint_rocker_right" type="fixed">
    <origin rpy="1.5708 -1.128 1.5708" xyz="0.176 -0.325 0.42252"/>
    <parent link="base_link"/>
    <child link="rocker_right"/>
    <axis xyz="1 0 0"/>
    <limit effort="1000" lower="0.3" upper="-1.41" velocity="0.5"/>
  </joint>
  <gazebo reference="rocker_right">
    <material>Gazebo/FlatBlack</material>
  </gazebo>
  <link name="L3">
    <inertial>
      <origin rpy="0 0 0" xyz="-0.0908549897031921 5.55111512312578E-17 2.22044604925031E-16"/>
      <mass value="9.18939845373489"/>
      <inertia ixx="0.0874656518269331" ixy="2.04857662106961E-18" ixz="-7.21103695768604E-19" iyy="0.065169129886498" iyz="1.73472347597681E-18" izz="0.065169129886498"/>
    </inertial>
    <visual>
      <origin rpy="0 0 0" xyz="0 0 0"/>
      <geometry>
        <mesh filename="package://robot1/meshes/L3.stl"/>
      </geometry>
      <material name="">
        <color rgba="0.901960784313726 0.92156862745098 0.92156862745098 1"/>
      </material>
    </visual>
    <collision>
      <origin rpy="0 0 0" xyz="0 0 0"/>
      <geometry>
        <mesh filename="package://robot1/meshes/L3.stl"/>
      </geometry>
    </collision>
  </link>
  <joint name="JL3" type="continuous">
    <origin rpy="1.02773942730628 1.5707963267949 0" xyz="-0.32500000000001 0 0.0935000000000011"/>
    <parent link="rocker_right"/>
    <child link="L3"/>
    <axis xyz="-1 0 0"/>
  </joint>
  <gazebo reference="L3">
    <material>Gazebo/Gold</material>
    <mu1>0.63</mu1>
    <mu2>0.65</mu2>
  </gazebo>
  <link name="rocker_left">
    <inertial>
      <origin rpy="0 0 0" xyz="-0.160266603892046 1.23013324715426E-06 -0.0749142147807064"/>
      <mass value="0.87054039948277"/>
      <inertia ixx="0.000476173012417757" ixy="1.28337652397967E-07" ixz="-0.00107017307922966" iyy="0.0173103434352455" iyz="1.15696080347409E-08" izz="0.0171520675067954"/>
    </inertial>
    <visual>
      <origin rpy="0 0 0" xyz="0 0 0"/>
      <geometry>
        <mesh filename="package://robot1/meshes/rocker_left.stl"/>
      </geometry>
      <material name="">
        <color rgba="0.898039215686275 0.917647058823529 0.929411764705882 1"/>
      </material>
    </visual>
    <collision>
      <origin rpy="0 0 0" xyz="0 0 0"/>
      <geometry>
        <mesh filename="package://robot1/meshes/rocker_left.stl"/>
      </geometry>
    </collision>
  </link>
  <joint name="joint_rocker_left" type="fixed">
    <origin rpy="1.5707963267949 -1.12802356646369 1.5707963267949" xyz="-0.176000000000002 -0.325 0.422517935490558"/>
    <parent link="base_link"/>
    <child link="rocker_left"/>
    <axis xyz="1 0 0"/>
    <limit effort="1000" lower="0.3" upper="-1.41" velocity="0.5"/>
  </joint>
  <gazebo reference="rocker_left">
    <material>Gazebo/FlatBlack</material>
  </gazebo>
  <link name="L6">
    <inertial>
      <origin rpy="0 0 0" xyz="-0.0908549897031923 2.77555756156289E-17 3.88578058618805E-16"/>
      <mass value="9.18939845373489"/>
      <inertia ixx="0.087465651826933" ixy="-5.19487396286121E-18" ixz="-1.55243062501977E-17" iyy="0.065169129886498" iyz="5.33969569949111E-18" izz="0.065169129886498"/>
    </inertial>
    <visual>
      <origin rpy="0 0 0" xyz="0 0 0"/>
      <geometry>
        <mesh filename="package://robot1/meshes/L6.stl"/>
      </geometry>
      <material name="">
        <color rgba="0.901960784313726 0.92156862745098 0.92156862745098 1"/>
      </material>
    </visual>
    <collision>
      <origin rpy="0 0 0" xyz="0 0 0"/>
      <geometry>
        <mesh filename="package://robot1/meshes/L6.stl"/>
      </geometry>
    </collision>
  </link>
  <joint name="JL6" type="continuous">
    <origin rpy="1.12616631715067 -1.5707963267949 0" xyz="-0.325 0 -0.0934999999999984"/>
    <parent link="rocker_left"/>
    <child link="L6"/>
    <axis xyz="1 0 0"/>
  </joint>
  <gazebo reference="L6">
    <material>Gazebo/Gold</material>
    <mu1>0.63</mu1>
    <mu2>0.65</mu2>
  </gazebo>
  <gazebo>
  <plugin name="skid_steer_drive_controller" filename="libgazebo_ros_skid_steer_drive.so">
    <updateRate>100.0</updateRate>
    <robotNamespace>/</robotNamespace>
    <leftFrontJoint>JL4</leftFrontJoint>
    <rightFrontJoint>JL1</rightFrontJoint>
    <leftRearJoint>JL6</leftRearJoint>
    <rightRearJoint>JL3</rightRearJoint>
    <rightMiddleJoint>JL2</rightMiddleJoint>
    <leftMiddleJoint>JL5</leftMiddleJoint>
    <wheelSeparation>0.7</wheelSeparation>
    <wheelDiameter>0.3</wheelDiameter>
    <robotBaseFrame>base_link</robotBaseFrame>
    <torque>100</torque>
    <topicName>cmd_vel</topicName>
    <broadcastTF>true</broadcastTF>
  </plugin>
</gazebo>
</robot>

