<?xml version="1.0" ?>
<!-- =================================================================================== -->
<!-- |    This document was autogenerated by xacro from ROVER2018.sdf                  | -->
<!-- |    EDITING THIS FILE BY HAND IS NOT RECOMMENDED                                 | -->
<!-- =================================================================================== -->
<sdf version="1.5">
  <model name="ROVER2018" xmlns:xacro="http://www.ros.org/wiki/xacro">
    <pose>0 0 -0.206146516789946 0 0 0</pose>
    <plugin filename="libgz_clock.so" name="clock">
      <topic>/gazebo/frc/time</topic>
    </plugin>
    <link name="Chassis">
      <gravity>1</gravity>
      <self_collide>0</self_collide>
      <pose>0.0563659925775667 -0.199999999999971 0.0647539612541443 1.57079632679496 5.53112244015523E-14 4.23969128033834E-15</pose>
      <must_be_base_link>1</must_be_base_link>
      <velocity_decay>
        <linear>0</linear>
        <angular>0</angular>
      </velocity_decay>
      <inertial>
        <mass>4.69449296226058</mass>
        <pose>0 0 0 0 0 0</pose>
        <inertia>
          <ixx>0.188223349582569</ixx>
          <ixy>0.000494545543801884</ixy>
          <ixz>1.28836069417104E-13</ixz>
          <iyy>0.710366145165714</iyy>
          <iyz>5.9410740148552E-14</iyz>
          <izz>0.560685653312675</izz>
        </inertia>
      </inertial>
      <collision name="Chassis_collision">
        <pose>-0.0263659925775535 0.00524603874597129 2.00646410801813E-14 0 0 0</pose>
        <geometry>
          <mesh>
            <scale>1 1 1</scale>
            <uri>model://ROVER2018/meshes/Chassis_col.STL</uri>
          </mesh>
        </geometry>
        <surface>
          <contact>
            <ode/>
          </contact>
          <friction>
            <ode>
              <mu>0</mu>
              <mu2>0</mu2>
            </ode>
          </friction>
        </surface>
      </collision>
      <visual name="Chassis_visual">
        <pose>-0.0263659925775535 0.00524603874597129 2.00646410801813E-14 0 0 0</pose>
        <material>
          <ambient>1 0 0 1</ambient>
          <diffuse>1 0 0 1</diffuse>
        </material>
        <geometry>
          <mesh>
            <scale>1 1 1</scale>
            <uri>model://ROVER2018/meshes/Chassis.STL</uri>
          </mesh>
        </geometry>
      </visual>
    </link>
    <link name="RFU">
      <gravity>1</gravity>
      <self_collide>0</self_collide>
      <pose>0.552789857987023 -0.556027945623617 -0.00574792509967748 1.57079632679496 5.53112244015523E-14 4.23969128033834E-15</pose>
      <must_be_base_link>0</must_be_base_link>
      <velocity_decay>
        <linear>0</linear>
        <angular>0</angular>
      </velocity_decay>
      <inertial>
        <mass>0.297872414793912</mass>
        <pose>0 0 0 0 0 0</pose>
        <inertia>
          <ixx>0.00149067915826456</ixx>
          <ixy>0.000437911415490614</ixy>
          <ixz>0.00100961344297201</ixz>
          <iyy>0.00312385673503285</iyy>
          <iyz>0.000542372766800571</iyz>
          <izz>0.00210865524412536</izz>
        </inertia>
      </inertial>
      <visual name="RFU_visual">
        <pose>-0.522789857987012 0.0757479250997438 -0.356027945623633 0 0 0</pose>
        <material>
          <ambient>1 0 0 1</ambient>
          <diffuse>1 0 0 1</diffuse>
        </material>
        <geometry>
          <mesh>
            <scale>1 1 1</scale>
            <uri>model://ROVER2018/meshes/RFU.STL</uri>
          </mesh>
        </geometry>
      </visual>
    </link>
    <joint name="Chassis-RFU" type="revolute">
      <parent>Chassis</parent>
      <child>RFU</child>
      <pose>-2.16493489801906E-14 0.0557479250991992 -0.128527945623614 0 0 0</pose>
      <axis>
        <xyz>-1 5.30527477495469E-14 -4.65515099183086E-15</xyz>
        <dynamics>
          <damping>0</damping>
          <friction>0</friction>
        </dynamics>
        <limit>
          <upper>0.409251555336729</upper>
          <lower>-0.409251555336729</lower>
          <effort>1</effort>
        </limit>
      </axis>
    </joint>
    <link name="RFL">
      <gravity>1</gravity>
      <self_collide>0</self_collide>
      <pose>0.53204172648251 -0.535187484996348 -0.0440794112806232 1.57079632679496 5.53112244015523E-14 4.23969128033834E-15</pose>
      <must_be_base_link>0</must_be_base_link>
      <velocity_decay>
        <linear>0</linear>
        <angular>0</angular>
      </velocity_decay>
      <inertial>
        <mass>0.347157094003806</mass>
        <pose>0 0 0 0 0 0</pose>
        <inertia>
          <ixx>0.00235501478870573</ixx>
          <ixy>0.000733786522324321</ixy>
          <ixz>0.00155907101871212</ixz>
          <iyy>0.00384054138899661</iyy>
          <iyz>0.000894672074835313</iyz>
          <izz>0.00237082269949256</izz>
        </inertia>
      </inertial>
      <visual name="RFL_visual">
        <pose>-0.502041726482501 0.114079411280692 -0.335187484996366 0 0 0</pose>
        <material>
          <ambient>1 0 0 1</ambient>
          <diffuse>1 0 0 1</diffuse>
        </material>
        <geometry>
          <mesh>
            <scale>1 1 1</scale>
            <uri>model://ROVER2018/meshes/RFL.STL</uri>
          </mesh>
        </geometry>
      </visual>
    </link>
    <joint name="Chassis-RFL" type="revolute">
      <parent>Chassis</parent>
      <child>RFL</child>
      <pose>-2.72004641033163E-14 0.0440794112804916 -0.107687484996349 0 0 0</pose>
      <axis>
        <xyz>-1 -5.3560383141516E-14 -4.21549682201188E-15</xyz>
        <dynamics>
          <damping>10092.6</damping>
          <friction>0</friction>
        </dynamics>
        <limit>
          <upper>0.409251555337445</upper>
          <lower>-0.409251555337445</lower>
          <effort>1</effort>
        </limit>
      </axis>
    </joint>
    <link name="RMU">
      <gravity>1</gravity>
      <self_collide>0</self_collide>
      <pose>0.0499999999999955 -0.562507985968966 -0.00722514883933886 1.57079632679496 5.53112244015523E-14 4.23969128033834E-15</pose>
      <must_be_base_link>0</must_be_base_link>
      <velocity_decay>
        <linear>0</linear>
        <angular>0</angular>
      </velocity_decay>
      <inertial>
        <mass>0.219182492008443</mass>
        <pose>0 0 0 0 0 0</pose>
        <inertia>
          <ixx>0.00139018081372786</ixx>
          <ixy>2.52047505057948E-17</ixy>
          <ixz>2.78889758628939E-17</ixz>
          <iyy>0.00190073445590091</iyy>
          <iyz>0.000498189225471237</iyz>
          <izz>0.000936550347206733</izz>
        </inertia>
      </inertial>
      <visual name="RMU_visual">
        <pose>-0.0199999999999848 0.0772251488394326 -0.362507985968979 0 0 0</pose>
        <material>
          <ambient>1 0 0 1</ambient>
          <diffuse>1 0 0 1</diffuse>
        </material>
        <geometry>
          <mesh>
            <scale>1 1 1</scale>
            <uri>model://ROVER2018/meshes/RMU.STL</uri>
          </mesh>
        </geometry>
      </visual>
    </link>
    <joint name="Chassis-RMU" type="revolute">
      <parent>Chassis</parent>
      <child>RMU</child>
      <pose>-1.08663078535187E-14 0.0572251488389147 -0.135007985968963 0 0 0</pose>
      <axis>
        <xyz>-1 5.30527477495469E-14 -4.65515099183086E-15</xyz>
        <dynamics>
          <damping>0</damping>
          <friction>0</friction>
        </dynamics>
        <limit>
          <upper>0.400908829671745</upper>
          <lower>-0.400908829671745</lower>
          <effort>1</effort>
        </limit>
      </axis>
    </joint>
    <link name="RML">
      <gravity>1</gravity>
      <self_collide>0</self_collide>
      <pose>0.0500138398239274 -0.533448505161519 -0.0419146372849672 1.57079632679496 5.53112244015523E-14 4.23969128033834E-15</pose>
      <must_be_base_link>0</must_be_base_link>
      <velocity_decay>
        <linear>0</linear>
        <angular>0</angular>
      </velocity_decay>
      <inertial>
        <mass>0.303841816239992</mass>
        <pose>0 0 0 0 0 0</pose>
        <inertia>
          <ixx>0.00228583211098358</ixx>
          <ixy>2.15210110154016E-07</ixy>
          <ixz>3.05698265978717E-07</ixz>
          <iyy>0.00238791677632981</iyy>
          <iyz>0.00085648000105561</iyz>
          <izz>0.000932831073544188</izz>
        </inertia>
      </inertial>
      <visual name="RML_visual">
        <pose>-0.0200138398239187 0.111914637285063 -0.333448505161534 0 0 0</pose>
        <material>
          <ambient>1 0 0 1</ambient>
          <diffuse>1 0 0 1</diffuse>
        </material>
        <geometry>
          <mesh>
            <scale>1 1 1</scale>
            <uri>model://ROVER2018/meshes/RML.STL</uri>
          </mesh>
        </geometry>
      </visual>
    </link>
    <joint name="Chassis-RML" type="revolute">
      <parent>Chassis</parent>
      <child>RML</child>
      <pose>-1.75554015768853E-15 0.0419146372848365 -0.105948505161519 0 0 0</pose>
      <axis>
        <xyz>-1 -5.3560383141516E-14 -4.21549682201188E-15</xyz>
        <dynamics>
          <damping>10092.6</damping>
          <friction>0</friction>
        </dynamics>
        <limit>
          <upper>0.400908829669831</upper>
          <lower>-0.400908829669831</lower>
          <effort>1</effort>
        </limit>
      </axis>
    </joint>
    <link name="RRU">
      <gravity>1</gravity>
      <self_collide>0</self_collide>
      <pose>-0.492789857987026 -0.555949800557489 -0.0059277453138713 1.57079632679496 5.53112244015523E-14 4.23969128033834E-15</pose>
      <must_be_base_link>0</must_be_base_link>
      <velocity_decay>
        <linear>0</linear>
        <angular>0</angular>
      </velocity_decay>
      <inertial>
        <mass>0.297872414793913</mass>
        <pose>0 0 0 0 0 0</pose>
        <inertia>
          <ixx>0.00149067915826455</ixx>
          <ixy>0.000439323940250268</ixy>
          <ixz>0.00100899959740813</ixz>
          <iyy>0.00312233664720994</iyy>
          <iyz>0.000543791414904701</iyz>
          <izz>0.00211017533194831</izz>
        </inertia>
      </inertial>
      <visual name="RRU_visual">
        <pose>0.522789857987036 0.0759277453139955 -0.3559498005575 0 0 0</pose>
        <material>
          <ambient>1 0 0 1</ambient>
          <diffuse>1 0 0 1</diffuse>
        </material>
        <geometry>
          <mesh>
            <scale>1 1 1</scale>
            <uri>model://ROVER2018/meshes/RRU.STL</uri>
          </mesh>
        </geometry>
      </visual>
    </link>
    <joint name="Chassis-RRU" type="revolute">
      <parent>Chassis</parent>
      <child>RRU</child>
      <pose>3.66373598126302E-15 0.0559277453135063 -0.128449800557486 0 0 0</pose>
      <axis>
        <xyz>-1 5.30527477495469E-14 -4.65515099183086E-15</xyz>
        <dynamics>
          <damping>0</damping>
          <friction>0</friction>
        </dynamics>
        <limit>
          <upper>0.410651055390324</upper>
          <lower>-0.410651055390324</lower>
          <effort>1</effort>
        </limit>
      </axis>
    </joint>
    <link name="RRL">
      <gravity>1</gravity>
      <self_collide>0</self_collide>
      <pose>-0.471841726482514 -0.535125690419669 -0.0442300767055858 1.57079632679496 5.53112244015523E-14 4.23969128033834E-15</pose>
      <must_be_base_link>0</must_be_base_link>
      <velocity_decay>
        <linear>0</linear>
        <angular>0</angular>
      </velocity_decay>
      <inertial>
        <mass>0.347157094003805</mass>
        <pose>0 0 0 0 0 0</pose>
        <inertia>
          <ixx>0.00235501478870603</ixx>
          <ixy>0.000735967722988771</ixy>
          <ixz>0.00155804255797187</ixz>
          <iyy>0.00383803432644377</iyy>
          <iyz>0.000896725438926092</iyz>
          <izz>0.00237332976204541</izz>
        </inertia>
      </inertial>
      <visual name="RRL_visual">
        <pose>0.501841726482523 0.11423007670571 -0.335125690419683 0 0 0</pose>
        <material>
          <ambient>1 0 0 1</ambient>
          <diffuse>1 0 0 1</diffuse>
        </material>
        <geometry>
          <mesh>
            <scale>1 1 1</scale>
            <uri>model://ROVER2018/meshes/RRL.STL</uri>
          </mesh>
        </geometry>
      </visual>
    </link>
    <joint name="Chassis-RRL" type="revolute">
      <parent>Chassis</parent>
      <child>RRL</child>
      <pose>-1.4432899320127E-15 0.044230076705456 -0.10762569041967 0 0 0</pose>
      <axis>
        <xyz>-1 -5.3560383141516E-14 -4.21549682201188E-15</xyz>
        <dynamics>
          <damping>10092.6</damping>
          <friction>0</friction>
        </dynamics>
        <limit>
          <upper>0.410651055390555</upper>
          <lower>-0.410651055390555</lower>
          <effort>1</effort>
        </limit>
      </axis>
    </joint>
    <link name="LFU">
      <gravity>1</gravity>
      <self_collide>0</self_collide>
      <pose>0.55278985798699 0.157854329714603 -0.00133237461654419 1.57079632679496 5.53112244015523E-14 4.23969128033834E-15</pose>
      <must_be_base_link>0</must_be_base_link>
      <velocity_decay>
        <linear>0</linear>
        <angular>0</angular>
      </velocity_decay>
      <inertial>
        <mass>0.297872414793911</mass>
        <pose>0 0 0 0 0 0</pose>
        <inertia>
          <ixx>0.00149067915826455</ixx>
          <ixy>0.000403226358447005</ixy>
          <ixz>0.0010239600655789</ixz>
          <iyy>0.00315964709230601</iyy>
          <iyz>0.000506510458361262</iyz>
          <izz>0.00207286488685221</izz>
        </inertia>
      </inertial>
      <visual name="LFU_visual">
        <pose>-0.522789857986982 0.0713323746166542 0.357854329714588 0 0 0</pose>
        <material>
          <ambient>1 0 0 1</ambient>
          <diffuse>1 0 0 1</diffuse>
        </material>
        <geometry>
          <mesh>
            <scale>1 1 1</scale>
            <uri>model://ROVER2018/meshes/LFU.STL</uri>
          </mesh>
        </geometry>
      </visual>
    </link>
    <joint name="Chassis-LFU" type="revolute">
      <parent>Chassis</parent>
      <child>LFU</child>
      <pose>-1.11022302462516E-15 0.0513323746162808 0.130354329714581 0 0 0</pose>
      <axis>
        <xyz>1 5.46775485072676E-14 -4.65873159937273E-15</xyz>
        <dynamics>
          <damping>0</damping>
          <friction>0</friction>
        </dynamics>
        <limit>
          <upper>0.375142442462269</upper>
          <lower>-0.375142442462269</lower>
          <effort>1</effort>
        </limit>
      </axis>
    </joint>
    <link name="LFL">
      <gravity>1</gravity>
      <self_collide>0</self_collide>
      <pose>0.531841726482484 0.13662806565242 -0.0403813596927592 1.57079632679496 5.53112244015523E-14 4.23969128033834E-15</pose>
      <must_be_base_link>0</must_be_base_link>
      <velocity_decay>
        <linear>0</linear>
        <angular>0</angular>
      </velocity_decay>
      <inertial>
        <mass>0.347157094003805</mass>
        <pose>0 0 0 0 0 0</pose>
        <inertia>
          <ixx>0.00235501478870581</ixx>
          <ixy>0.000680191490139074</ixy>
          <ixz>0.00158318812478977</ixz>
          <iyy>0.00389981774903263</iyy>
          <iyz>0.0008424991753351</iyz>
          <izz>0.00231154633945684</izz>
        </inertia>
      </inertial>
      <visual name="LFL_visual">
        <pose>-0.501841726482478 0.110381359692869 0.336628065652403 0 0 0</pose>
        <material>
          <ambient>1 0 0 1</ambient>
          <diffuse>1 0 0 1</diffuse>
        </material>
        <geometry>
          <mesh>
            <scale>1 1 1</scale>
            <uri>model://ROVER2018/meshes/LFL.STL</uri>
          </mesh>
        </geometry>
      </visual>
    </link>
    <joint name="Chassis-LFL" type="revolute">
      <parent>Chassis</parent>
      <child>LFL</child>
      <pose>-2.55351295663786E-15 0.0403813596926969 0.109128065652419 0 0 0</pose>
      <axis>
        <xyz>1 5.3257347728044E-14 4.16842516893872E-15</xyz>
        <dynamics>
          <damping>10092.6</damping>
          <friction>0</friction>
        </dynamics>
        <limit>
          <upper>0.375142442461781</upper>
          <lower>-0.375142442461781</lower>
          <effort>1</effort>
        </limit>
      </axis>
    </joint>
    <link name="LMU">
      <gravity>1</gravity>
      <self_collide>0</self_collide>
      <pose>0.0499999999999957 0.163048337651941 -0.00593319314052002 1.57079632679496 5.53112244015523E-14 4.23969128033834E-15</pose>
      <must_be_base_link>0</must_be_base_link>
      <velocity_decay>
        <linear>0</linear>
        <angular>0</angular>
      </velocity_decay>
      <inertial>
        <mass>0.219182492008443</mass>
        <pose>0 0 0 0 0 0</pose>
        <inertia>
          <ixx>0.00139018081372786</ixx>
          <ixy>2.99128528668646E-17</ixy>
          <ixz>2.39737167214258E-17</ixz>
          <iyy>0.0019101616432626</iyy>
          <iyz>0.000488890671081232</iyz>
          <izz>0.000927123159845045</izz>
        </inertia>
      </inertial>
      <visual name="LMU_visual">
        <pose>-0.0199999999999879 0.0759331931406582 0.363048337651928 0 0 0</pose>
        <material>
          <ambient>1 0 0 1</ambient>
          <diffuse>1 0 0 1</diffuse>
        </material>
        <geometry>
          <mesh>
            <scale>1 1 1</scale>
            <uri>model://ROVER2018/meshes/LMU.STL</uri>
          </mesh>
        </geometry>
      </visual>
    </link>
    <joint name="Chassis-LMU" type="revolute">
      <parent>Chassis</parent>
      <child>LMU</child>
      <pose>-1.69829428298129E-14 0.0559331931402573 0.135548337651923 0 0 0</pose>
      <axis>
        <xyz>1 5.46775485072676E-14 -4.65873159937273E-15</xyz>
        <dynamics>
          <damping>0</damping>
          <friction>0</friction>
        </dynamics>
        <limit>
          <upper>0.391358538169444</upper>
          <lower>-0.391358538169444</lower>
          <effort>1</effort>
        </limit>
      </axis>
    </joint>
    <link name="LML">
      <gravity>1</gravity>
      <self_collide>0</self_collide>
      <pose>0.0500138398239269 0.133843964438337 -0.0409009020957097 1.57079632679496 5.53112244015523E-14 4.23969128033834E-15</pose>
      <must_be_base_link>0</must_be_base_link>
      <velocity_decay>
        <linear>0</linear>
        <angular>0</angular>
      </velocity_decay>
      <inertial>
        <mass>0.303841816239992</mass>
        <pose>0 0 0 0 0 0</pose>
        <inertia>
          <ixx>0.00228583211098358</ixx>
          <ixy>2.12280832571498E-07</ixy>
          <ixz>3.07739613051626E-07</ixz>
          <iyy>0.00240414233744685</iyy>
          <iyz>0.000842428122378149</iyz>
          <izz>0.000916605512427144</izz>
        </inertia>
      </inertial>
      <visual name="LML_visual">
        <pose>-0.0200138398239209 0.110900902095846 0.333843964438322 0 0 0</pose>
        <material>
          <ambient>1 0 0 1</ambient>
          <diffuse>1 0 0 1</diffuse>
        </material>
        <geometry>
          <mesh>
            <scale>1 1 1</scale>
            <uri>model://ROVER2018/meshes/LML.STL</uri>
          </mesh>
        </geometry>
      </visual>
    </link>
    <joint name="Chassis-LML" type="revolute">
      <parent>Chassis</parent>
      <child>LML</child>
      <pose>-2.66800470605233E-15 0.0409009020956482 0.106343964438336 0 0 0</pose>
      <axis>
        <xyz>1 5.3257347728044E-14 4.16842516893872E-15</xyz>
        <dynamics>
          <damping>10092.6</damping>
          <friction>0</friction>
        </dynamics>
        <limit>
          <upper>0.391358538168266</upper>
          <lower>-0.391358538168266</lower>
          <effort>1</effort>
        </limit>
      </axis>
    </joint>
    <link name="LRU">
      <gravity>1</gravity>
      <self_collide>0</self_collide>
      <pose>-0.492789857982656 0.157756289206472 -0.0015806463831313 1.57079632679496 5.53112244015523E-14 4.23969128033834E-15</pose>
      <must_be_base_link>0</must_be_base_link>
      <velocity_decay>
        <linear>0</linear>
        <angular>0</angular>
      </velocity_decay>
      <inertial>
        <mass>0.297872414793912</mass>
        <pose>0 0 0 0 0 0</pose>
        <inertia>
          <ixx>0.00149067915826464</ixx>
          <ixy>0.000405176584225962</ixy>
          <ixz>0.00102318993722661</ixz>
          <iyy>0.00315771303533698</iyy>
          <iyz>0.000508577430241729</iyz>
          <izz>0.00207479894382117</izz>
        </inertia>
      </inertial>
      <visual name="LRU_visual">
        <pose>0.522789857982664 0.0715806463832992 0.357756289206461 0 0 0</pose>
        <material>
          <ambient>1 0 0 1</ambient>
          <diffuse>1 0 0 1</diffuse>
        </material>
        <geometry>
          <mesh>
            <scale>1 1 1</scale>
            <uri>model://ROVER2018/meshes/LRU.STL</uri>
          </mesh>
        </geometry>
      </visual>
    </link>
    <joint name="Chassis-LRU" type="revolute">
      <parent>Chassis</parent>
      <child>LRU</child>
      <pose>-1.66533453693773E-15 0.0515806463828686 0.130256289206459 0 0 0</pose>
      <axis>
        <xyz>1 5.46775485072676E-14 -4.65873159937273E-15</xyz>
        <dynamics>
          <damping>0</damping>
          <friction>0</friction>
        </dynamics>
        <limit>
          <upper>0.377047750022617</upper>
          <lower>-0.377047750022617</lower>
          <effort>1</effort>
        </limit>
      </axis>
    </joint>
    <link name="LRL">
      <gravity>1</gravity>
      <self_collide>0</self_collide>
      <pose>-0.471841726482524 0.136550928710948 -0.0405892087994715 1.57079632679496 5.53112244015523E-14 4.23969128033834E-15</pose>
      <must_be_base_link>0</must_be_base_link>
      <velocity_decay>
        <linear>0</linear>
        <angular>0</angular>
      </velocity_decay>
      <inertial>
        <mass>0.347157094003805</mass>
        <pose>0 0 0 0 0 0</pose>
        <inertia>
          <ixx>0.00235501478870605</ixx>
          <ixy>0.000683206714004817</ixy>
          <ixz>0.00158188927794317</ixz>
          <iyy>0.00389660155097319</iyy>
          <iyz>0.000845519196668986</iyz>
          <izz>0.00231476253751599</izz>
        </inertia>
      </inertial>
      <visual name="LRL_visual">
        <pose>0.50184172648253 0.110589208799637 0.336550928710934 0 0 0</pose>
        <material>
          <ambient>1 0 0 1</ambient>
          <diffuse>1 0 0 1</diffuse>
        </material>
        <geometry>
          <mesh>
            <scale>1 1 1</scale>
            <uri>model://ROVER2018/meshes/LRL.STL</uri>
          </mesh>
        </geometry>
      </visual>
    </link>
    <joint name="Chassis-LRL" type="revolute">
      <parent>Chassis</parent>
      <child>LRL</child>
      <pose>-2.22044604925031E-15 0.0405892087994112 0.109050928710946 0 0 0</pose>
      <axis>
        <xyz>1 5.3257347728044E-14 4.16842516893872E-15</xyz>
        <dynamics>
          <damping>10092.6</damping>
          <friction>0</friction>
        </dynamics>
        <limit>
          <upper>0.377047750022888</upper>
          <lower>-0.377047750022888</lower>
          <effort>1</effort>
        </limit>
      </axis>
    </joint>
    <link name="RFH">
      <gravity>1</gravity>
      <self_collide>0</self_collide>
      <pose>0.612999999999748 -0.738553350192266 -0.0658337173312292 1.57079632679496 5.53112244015523E-14 4.23969128033834E-15</pose>
      <must_be_base_link>0</must_be_base_link>
      <velocity_decay>
        <linear>0</linear>
        <angular>0</angular>
      </velocity_decay>
      <inertial>
        <mass>0.681586924154088</mass>
        <pose>0 0 0 0 0 0</pose>
        <inertia>
          <ixx>0.00218832030376486</ixx>
          <ixy>3.16098230642194E-17</ixy>
          <ixz>5.49264907494005E-16</ixz>
          <iyy>0.00229495907842186</iyy>
          <iyz>8.9966835203717E-05</iyz>
          <izz>0.00076007927291866</izz>
        </inertia>
      </inertial>
      <visual name="RFH_visual">
        <pose>-0.58299999999974 0.135833717331281 -0.538553350192285 0 0 0</pose>
        <material>
          <ambient>1 0 0 1</ambient>
          <diffuse>1 0 0 1</diffuse>
        </material>
        <geometry>
          <mesh>
            <scale>1 1 1</scale>
            <uri>model://ROVER2018/meshes/RFH.STL</uri>
          </mesh>
        </geometry>
      </visual>
    </link>
    <joint name="RFU-RFH" type="revolute">
      <parent>RFU</parent>
      <child>RFH</child>
      <pose>-2.56461518688411E-14 0.0113789817481627 -0.0702308881701318 0 0 0</pose>
      <axis>
        <xyz>1 5.43546689139399E-14 4.62592926927148E-15</xyz>
        <dynamics>
          <damping>0</damping>
          <friction>0</friction>
        </dynamics>
        <limit>
          <upper>0.409251555335029</upper>
          <lower>-0.409251555335029</lower>
          <effort>1</effort>
        </limit>
      </axis>
    </joint>
    <joint name="RFL-RFH" type="revolute">
      <parent>RFL</parent>
      <child>RFH</child>
      <pose>-2.29816166097407E-14 -0.0386210182517009 -0.0702308881702616 0 0 0</pose>
      <axis>
        <xyz>1 5.3198186596622E-14 4.62592926927148E-15</xyz>
        <dynamics>
          <damping>0</damping>
          <friction>0</friction>
        </dynamics>
        <limit>
          <upper>0.40925155533585</upper>
          <lower>-0.40925155533585</lower>
          <effort>1</effort>
        </limit>
      </axis>
    </joint>
    <link name="RMH">
      <gravity>1</gravity>
      <self_collide>0</self_collide>
      <pose>0.0500000000002225 -0.739416396584814 -0.0638209898420632 1.57079632679496 5.53112244015523E-14 4.23969128033834E-15</pose>
      <must_be_base_link>0</must_be_base_link>
      <velocity_decay>
        <linear>0</linear>
        <angular>0</angular>
      </velocity_decay>
      <inertial>
        <mass>0.681586924154086</mass>
        <pose>0 0 0 0 0 0</pose>
        <inertia>
          <ixx>0.00218832030376486</ixx>
          <ixy>4.11724323933269E-17</ixy>
          <ixz>4.78663613797262E-16</ixz>
          <iyy>0.00229495907842157</iyy>
          <iyz>8.99668352067492E-05</iyz>
          <izz>0.000760079272918943</izz>
        </inertia>
      </inertial>
      <visual name="RMH_visual">
        <pose>-0.0200000000002141 0.133820989842146 -0.539416396584831 0 0 0</pose>
        <material>
          <ambient>1 0 0 1</ambient>
          <diffuse>1 0 0 1</diffuse>
        </material>
        <geometry>
          <mesh>
            <scale>1 1 1</scale>
            <uri>model://ROVER2018/meshes/RMH.STL</uri>
          </mesh>
        </geometry>
      </visual>
    </link>
    <joint name="RMU-RMH" type="revolute">
      <parent>RMU</parent>
      <child>RMH</child>
      <pose>-1.14491749414469E-14 0.011378981748185 -0.0702308881701874 0 0 0</pose>
      <axis>
        <xyz>1 -1.9660199394403E-14 5.08852219619842E-14</xyz>
        <dynamics>
          <damping>0</damping>
          <friction>0</friction>
        </dynamics>
        <limit>
          <upper>0.400908829671752</upper>
          <lower>-0.400908829671752</lower>
          <effort>1</effort>
        </limit>
      </axis>
    </joint>
    <joint name="RML-RMH" type="revolute">
      <parent>RML</parent>
      <child>RMH</child>
      <pose>-1.74027459109993E-14 -0.0386210182516862 -0.0702308881701845 0 0 0</pose>
      <axis>
        <xyz>1 2.77555756156291E-14 -4.62592926927152E-14</xyz>
        <dynamics>
          <damping>0</damping>
          <friction>0</friction>
        </dynamics>
        <limit>
          <upper>0.400908829669942</upper>
          <lower>-0.400908829669942</lower>
          <effort>1</effort>
        </limit>
      </axis>
    </joint>
    <link name="RRH">
      <gravity>1</gravity>
      <self_collide>0</self_collide>
      <pose>-0.552799999999779 -0.738406929994535 -0.0661706459769416 1.57079632679496 5.53112244015523E-14 4.23969128033834E-15</pose>
      <must_be_base_link>0</must_be_base_link>
      <velocity_decay>
        <linear>0</linear>
        <angular>0</angular>
      </velocity_decay>
      <inertial>
        <mass>0.681586924154084</mass>
        <pose>0 0 0 0 0 0</pose>
        <inertia>
          <ixx>0.00218832030376488</ixx>
          <ixy>1.94621262839504E-17</ixy>
          <ixz>3.79251325809996E-16</ixz>
          <iyy>0.00229495907842156</iyy>
          <iyz>8.99668352063439E-05</iyz>
          <izz>0.000760079272918962</izz>
        </inertia>
      </inertial>
      <visual name="RRH_visual">
        <pose>0.582799999999788 0.136170645977058 -0.53840692999455 0 0 0</pose>
        <material>
          <ambient>1 0 0 1</ambient>
          <diffuse>1 0 0 1</diffuse>
        </material>
        <geometry>
          <mesh>
            <scale>1 1 1</scale>
            <uri>model://ROVER2018/meshes/RRH.STL</uri>
          </mesh>
        </geometry>
      </visual>
    </link>
    <joint name="RRU-RRH" type="revolute">
      <parent>RRU</parent>
      <child>RRH</child>
      <pose>3.33066907387547E-15 0.011378981748208 -0.0702308881701607 0 0 0</pose>
      <axis>
        <xyz>1 -1.96601993944038E-14 5.08852219619863E-14</xyz>
        <dynamics>
          <damping>0</damping>
          <friction>0</friction>
        </dynamics>
        <limit>
          <upper>0.41065105539033</upper>
          <lower>-0.41065105539033</lower>
          <effort>1</effort>
        </limit>
      </axis>
    </joint>
    <joint name="RRL-RRH" type="revolute">
      <parent>RRL</parent>
      <child>RRH</child>
      <pose>-2.66453525910038E-15 -0.0386210182516423 -0.0702308881701924 0 0 0</pose>
      <axis>
        <xyz>1 2.77555756156289E-14 -4.62592926927148E-14</xyz>
        <dynamics>
          <damping>0</damping>
          <friction>0</friction>
        </dynamics>
        <limit>
          <upper>0.410651055390667</upper>
          <lower>-0.410651055390667</lower>
          <effort>1</effort>
        </limit>
      </axis>
    </joint>
    <link name="LFH">
      <gravity>1</gravity>
      <self_collide>0</self_collide>
      <pose>0.61299999999974 0.341975441094509 -0.0575603124044178 1.57079632679496 5.53112244015523E-14 4.23969128033834E-15</pose>
      <must_be_base_link>0</must_be_base_link>
      <velocity_decay>
        <linear>0</linear>
        <angular>0</angular>
      </velocity_decay>
      <inertial>
        <mass>0.681586924154087</mass>
        <pose>0 0 0 0 0 0</pose>
        <inertia>
          <ixx>0.00218832030376494</ixx>
          <ixy>1.96274474537766E-17</ixy>
          <ixz>4.24248310093578E-16</ixz>
          <iyy>0.00229495907842159</iyy>
          <iyz>8.99668352052444E-05</iyz>
          <izz>0.000760079272919003</izz>
        </inertia>
      </inertial>
      <visual name="LFH_visual">
        <pose>-0.582999999999736 0.127560312404536 0.54197544109449 0 0 0</pose>
        <material>
          <ambient>1 0 0 1</ambient>
          <diffuse>1 0 0 1</diffuse>
        </material>
        <geometry>
          <mesh>
            <scale>1 1 1</scale>
            <uri>model://ROVER2018/meshes/LFH.STL</uri>
          </mesh>
        </geometry>
      </visual>
    </link>
    <joint name="LFU-LFH" type="revolute">
      <parent>LFU</parent>
      <child>LFH</child>
      <pose>-2.44249065417534E-15 0.00743110801386251 0.0718226182630399 0 0 0</pose>
      <axis>
        <xyz>-1 1.9660199394403E-14 -5.08852219619842E-14</xyz>
        <dynamics>
          <damping>0</damping>
          <friction>0</friction>
        </dynamics>
        <limit>
          <upper>0.375142442462172</upper>
          <lower>-0.375142442462172</lower>
          <effort>1</effort>
        </limit>
      </axis>
    </joint>
    <joint name="LFL-LFH" type="revolute">
      <parent>LFL</parent>
      <child>LFH</child>
      <pose>5.55111512312578E-15 -0.0390862043851232 0.0704145864035264 0 0 0</pose>
      <axis>
        <xyz>-1 -2.77555756156289E-14 4.62592926927148E-14</xyz>
        <dynamics>
          <damping>0</damping>
          <friction>0</friction>
        </dynamics>
        <limit>
          <upper>0.375142442461684</upper>
          <lower>-0.375142442461684</lower>
          <effort>1</effort>
        </limit>
      </axis>
    </joint>
    <link name="LMH">
      <gravity>1</gravity>
      <self_collide>0</self_collide>
      <pose>0.0499999999997582 0.340383711001693 -0.0615081861386884 1.57079632679496 5.53112244015523E-14 4.23969128033834E-15</pose>
      <must_be_base_link>0</must_be_base_link>
      <velocity_decay>
        <linear>0</linear>
        <angular>0</angular>
      </velocity_decay>
      <inertial>
        <mass>0.681586924154086</mass>
        <pose>0 0 0 0 0 0</pose>
        <inertia>
          <ixx>0.00218832030376486</ixx>
          <ixy>2.62855629839107E-17</ixy>
          <ixz>4.30581394860095E-16</ixz>
          <iyy>0.00229495907842158</iyy>
          <iyz>8.99668352063507E-05</iyz>
          <izz>0.000760079272918938</izz>
        </inertia>
      </inertial>
      <visual name="LMH_visual">
        <pose>-0.0199999999997543 0.131508186138837 0.540383711001676 0 0 0</pose>
        <material>
          <ambient>1 0 0 1</ambient>
          <diffuse>1 0 0 1</diffuse>
        </material>
        <geometry>
          <mesh>
            <scale>1 1 1</scale>
            <uri>model://ROVER2018/meshes/LMH.STL</uri>
          </mesh>
        </geometry>
      </visual>
    </link>
    <joint name="LMU-LMH" type="revolute">
      <parent>LMU</parent>
      <child>LMH</child>
      <pose>-1.72327430103536E-14 0.0113789817481752 0.0702308881701975 0 0 0</pose>
      <axis>
        <xyz>-1 1.9660199394403E-14 -5.08852219619842E-14</xyz>
        <dynamics>
          <damping>0</damping>
          <friction>0</friction>
        </dynamics>
        <limit>
          <upper>0.391358538169387</upper>
          <lower>-0.391358538169387</lower>
          <effort>1</effort>
        </limit>
      </axis>
    </joint>
    <joint name="LML-LMH" type="revolute">
      <parent>LML</parent>
      <child>LMH</child>
      <pose>-1.81486770056694E-14 -0.0386210182516963 0.0702308881701973 0 0 0</pose>
      <axis>
        <xyz>-1 -6.93889390390722E-15 -6.47630097698007E-14</xyz>
        <dynamics>
          <damping>0</damping>
          <friction>0</friction>
        </dynamics>
        <limit>
          <upper>0.391358538168169</upper>
          <lower>-0.391358538168169</lower>
          <effort>1</effort>
        </limit>
      </axis>
    </joint>
    <link name="LRH">
      <gravity>1</gravity>
      <self_collide>0</self_collide>
      <pose>-0.552999999995367 0.341791742861149 -0.0580254985378351 1.57079632679496 5.53112244015523E-14 4.23969128033834E-15</pose>
      <must_be_base_link>0</must_be_base_link>
      <velocity_decay>
        <linear>0</linear>
        <angular>0</angular>
      </velocity_decay>
      <inertial>
        <mass>0.681586924154064</mass>
        <pose>0 0 0 0 0 0</pose>
        <inertia>
          <ixx>0.00218832030376473</ixx>
          <ixy>2.80977769263197E-17</ixy>
          <ixz>4.31051678725924E-16</ixz>
          <iyy>0.00229495907842147</iyy>
          <iyz>8.99668352066864E-05</iyz>
          <izz>0.000760079272918898</izz>
        </inertia>
      </inertial>
      <visual name="LRH_visual">
        <pose>0.582999999995371 0.128025498538018 0.541791742861135 0 0 0</pose>
        <material>
          <ambient>1 0 0 1</ambient>
          <diffuse>1 0 0 1</diffuse>
        </material>
        <geometry>
          <mesh>
            <scale>1 1 1</scale>
            <uri>model://ROVER2018/meshes/LRH.STL</uri>
          </mesh>
        </geometry>
      </visual>
    </link>
    <joint name="LRU-LRH" type="revolute">
      <parent>LRU</parent>
      <child>LRH</child>
      <pose>2.66453525910038E-15 0.0118441678815934 0.0700471899368895 0 0 0</pose>
      <axis>
        <xyz>-1 -2.89120579329462E-14 4.6259292692714E-14</xyz>
        <dynamics>
          <damping>0</damping>
          <friction>0</friction>
        </dynamics>
        <limit>
          <upper>0.37704775002256</upper>
          <lower>-0.37704775002256</lower>
          <effort>1</effort>
        </limit>
      </axis>
    </joint>
    <joint name="LRL-LRH" type="revolute">
      <parent>LRL</parent>
      <child>LRH</child>
      <pose>3.77475828372553E-15 -0.0381558321182717 0.0700471899368866 0 0 0</pose>
      <axis>
        <xyz>-1 -2.77555756156279E-14 4.16333634234418E-14</xyz>
        <dynamics>
          <damping>0</damping>
          <friction>0</friction>
        </dynamics>
        <limit>
          <upper>0.377047750022791</upper>
          <lower>-0.377047750022791</lower>
          <effort>1</effort>
        </limit>
      </axis>
    </joint>
    <link name="RFW">
      <gravity>1</gravity>
      <self_collide>0</self_collide>
      <pose>0.613000605023412 -0.766878389708996 -0.0639549061460528 1.57079632679496 5.53112244015523E-14 4.23969128033834E-15</pose>
      <must_be_base_link>0</must_be_base_link>
      <velocity_decay>
        <linear>0</linear>
        <angular>0</angular>
      </velocity_decay>
      <inertial>
        <mass>12.4300428436696</mass>
        <pose>0 0 0 0 0 0</pose>
        <inertia>
          <ixx>0.0969800086894888</ixx>
          <ixy>1.32913414151678E-08</ixy>
          <ixz>4.58328084302638E-07</ixz>
          <iyy>0.0969799652892245</iyy>
          <iyz>1.29207788532721E-07</iyz>
          <izz>0.146035944406481</izz>
        </inertia>
      </inertial>
      <collision name="RFW_collision">
        <pose>-0.583000605023404 0.133954906146103 -0.566878389709016 0 0 0</pose>
        <geometry>
          <mesh>
            <scale>1 1 1</scale>
            <uri>model://ROVER2018/meshes/RFW_col.STL</uri>
          </mesh>
        </geometry>
        <surface>
          <contact>
            <ode/>
          </contact>
          <friction>
            <ode>
              <mu>0</mu>
              <mu2>0</mu2>
            </ode>
          </friction>
        </surface>
      </collision>
      <visual name="RFW_visual">
        <pose>-0.583000605023404 0.133954906146103 -0.566878389709016 0 0 0</pose>
        <material>
          <ambient>1 0 0 1</ambient>
          <diffuse>1 0 0 1</diffuse>
        </material>
        <geometry>
          <mesh>
            <scale>1 1 1</scale>
            <uri>model://ROVER2018/meshes/RFW.STL</uri>
          </mesh>
        </geometry>
      </visual>
    </link>
    <joint name="RFH-RFW" type="revolute">
      <parent>RFH</parent>
      <child>RFW</child>
      <pose>-6.05023693811546E-07 1.70563189377804E-07 0.000614700361304177 0 0 0</pose>
      <axis>
        <xyz>1.68946982008199E-13 1.60740985739229E-12 -1</xyz>
        <dynamics>
          <damping>0</damping>
          <friction>0.3</friction>
        </dynamics>
        <limit>
          <effort>1</effort>
        </limit>
      </axis>
    </joint>
    <link name="RMW">
      <gravity>1</gravity>
      <self_collide>0</self_collide>
      <pose>0.0500000000003371 -0.764724619531073 -0.0619420080937991 1.57079632679496 5.53112244015523E-14 4.23969128033834E-15</pose>
      <must_be_base_link>0</must_be_base_link>
      <velocity_decay>
        <linear>0</linear>
        <angular>0</angular>
      </velocity_decay>
      <inertial>
        <mass>11.446866621584</mass>
        <pose>0 0 0 0 0 0</pose>
        <inertia>
          <ixx>0.0935688544901957</ixx>
          <ixy>9.71003317221151E-19</ixy>
          <ixz>2.30899935759149E-16</ixz>
          <iyy>0.0935688544901957</iyy>
          <iyz>3.11670917360068E-15</iyz>
          <izz>0.144062067352231</izz>
        </inertia>
      </inertial>
      <collision name="RMW_collision">
        <pose>-0.0200000000003285 0.13194200809388 -0.564724619531089 0 0 0</pose>
        <geometry>
          <mesh>
            <scale>1 1 1</scale>
            <uri>model://ROVER2018/meshes/RMW_col.STL</uri>
          </mesh>
        </geometry>
        <surface>
          <contact>
            <ode/>
          </contact>
          <friction>
            <ode>
              <mu>0</mu>
              <mu2>0</mu2>
            </ode>
          </friction>
        </surface>
      </collision>
      <visual name="RMW_visual">
        <pose>-0.0200000000003285 0.13194200809388 -0.564724619531089 0 0 0</pose>
        <material>
          <ambient>1 0 0 1</ambient>
          <diffuse>1 0 0 1</diffuse>
        </material>
        <geometry>
          <mesh>
            <scale>1 1 1</scale>
            <uri>model://ROVER2018/meshes/RMW.STL</uri>
          </mesh>
        </geometry>
      </visual>
    </link>
    <joint name="RMH-RMW" type="revolute">
      <parent>RMH</parent>
      <child>RMW</child>
      <pose>-8.07191119500672E-13 0.00231280370325745 -3.66373598126302E-14 0 0 0</pose>
      <axis>
        <xyz>2.00322850095409E-13 -5.43043870740565E-14 -1</xyz>
        <dynamics>
          <damping>0</damping>
          <friction>0.3</friction>
        </dynamics>
        <limit>
          <effort>1</effort>
        </limit>
      </axis>
    </joint>
    <link name="RRW">
      <gravity>1</gravity>
      <self_collide>0</self_collide>
      <pose>-0.55279999999969 -0.763715152940898 -0.0642916642286606 1.57079632679496 5.53112244015523E-14 4.23969128033834E-15</pose>
      <must_be_base_link>0</must_be_base_link>
      <velocity_decay>
        <linear>0</linear>
        <angular>0</angular>
      </velocity_decay>
      <inertial>
        <mass>11.446866621584</mass>
        <pose>0 0 0 0 0 0</pose>
        <inertia>
          <ixx>0.0935688544901957</ixx>
          <ixy>1.3322561946054E-17</ixy>
          <ixz>2.39538975607886E-16</ixz>
          <iyy>0.0935688544901957</iyy>
          <iyz>3.10734872551274E-15</iyz>
          <izz>0.144062067352231</izz>
        </inertia>
      </inertial>
      <collision name="RRW_collision">
        <pose>0.582799999999698 0.134291664228775 -0.563715152940913 0 0 0</pose>
        <geometry>
          <mesh>
            <scale>1 1 1</scale>
            <uri>model://ROVER2018/meshes/RRW_col.STL</uri>
          </mesh>
        </geometry>
        <surface>
          <contact>
            <ode/>
          </contact>
          <friction>
            <ode>
              <mu>0</mu>
              <mu2>0</mu2>
            </ode>
          </friction>
        </surface>
      </collision>
      <visual name="RRW_visual">
        <pose>0.582799999999698 0.134291664228775 -0.563715152940913 0 0 0</pose>
        <material>
          <ambient>1 0 0 1</ambient>
          <diffuse>1 0 0 1</diffuse>
        </material>
        <geometry>
          <mesh>
            <scale>1 1 1</scale>
            <uri>model://ROVER2018/meshes/RRW.STL</uri>
          </mesh>
        </geometry>
      </visual>
    </link>
    <joint name="RRH-RRW" type="revolute">
      <parent>RRH</parent>
      <child>RRW</child>
      <pose>-9.68114477473137E-14 -1.02695629777827E-13 -3.88578058618805E-14 0 0 0</pose>
      <axis>
        <xyz>1.68946982008176E-13 -4.94773304452515E-14 -1</xyz>
        <dynamics>
          <damping>0</damping>
          <friction>0.3</friction>
        </dynamics>
        <limit>
          <effort>1</effort>
        </limit>
      </axis>
    </joint>
    <link name="LFW">
      <gravity>1</gravity>
      <self_collide>0</self_collide>
      <pose>0.612999999999626 0.367283664040887 -0.055681330656202 1.57079632679496 5.53112244015523E-14 4.23969128033834E-15</pose>
      <must_be_base_link>0</must_be_base_link>
      <velocity_decay>
        <linear>0</linear>
        <angular>0</angular>
      </velocity_decay>
      <inertial>
        <mass>11.446866621584</mass>
        <pose>0 0 0 0 0 0</pose>
        <inertia>
          <ixx>0.0935688544901956</ixx>
          <ixy>1.01689415961673E-17</ixy>
          <ixz>2.41003439859397E-16</ixz>
          <iyy>0.0935688544901956</iyy>
          <iyz>3.11661970568523E-15</iyz>
          <izz>0.144062067352231</izz>
        </inertia>
      </inertial>
      <collision name="LFW_collision">
        <pose>-0.582999999999622 0.125681330656322 0.567283664040868 0 0 0</pose>
        <geometry>
          <mesh>
            <scale>1 1 1</scale>
            <uri>model://ROVER2018/meshes/LFW_col.STL</uri>
          </mesh>
        </geometry>
        <surface>
          <contact>
            <ode/>
          </contact>
          <friction>
            <ode>
              <mu>0</mu>
              <mu2>0</mu2>
            </ode>
          </friction>
        </surface>
      </collision>
      <visual name="LFW_visual">
        <pose>-0.582999999999622 0.125681330656322 0.567283664040868 0 0 0</pose>
        <material>
          <ambient>1 0 0 1</ambient>
          <diffuse>1 0 0 1</diffuse>
        </material>
        <geometry>
          <mesh>
            <scale>1 1 1</scale>
            <uri>model://ROVER2018/meshes/LFW.STL</uri>
          </mesh>
        </geometry>
      </visual>
    </link>
    <joint name="LFH-LFW" type="revolute">
      <parent>LFH</parent>
      <child>LFW</child>
      <pose>1.16573417585641E-13 -8.75410854916936E-14 3.27515792264421E-14 0 0 0</pose>
      <axis>
        <xyz>1.97909321781006E-13 -5.43043870740565E-14 -1</xyz>
        <dynamics>
          <damping>0</damping>
          <friction>0.3</friction>
        </dynamics>
        <limit>
          <effort>1</effort>
        </limit>
      </axis>
    </joint>
    <link name="LMW">
      <gravity>1</gravity>
      <self_collide>0</self_collide>
      <pose>0.0499999999996457 0.365691933947957 -0.0596292043904403 1.57079632679496 5.53112244015523E-14 4.23969128033834E-15</pose>
      <must_be_base_link>0</must_be_base_link>
      <velocity_decay>
        <linear>0</linear>
        <angular>0</angular>
      </velocity_decay>
      <inertial>
        <mass>11.446866621584</mass>
        <pose>0 0 0 0 0 0</pose>
        <inertia>
          <ixx>0.0935688544901957</ixx>
          <ixy>7.50256119437606E-18</ixy>
          <ixz>2.20993128546076E-16</ixz>
          <iyy>0.0935688544901957</iyy>
          <iyz>2.6276341235303E-15</iyz>
          <izz>0.144062067352231</izz>
        </inertia>
      </inertial>
      <collision name="LMW_collision">
        <pose>-0.0199999999996418 0.129629204390591 0.56569193394794 0 0 0</pose>
        <geometry>
          <mesh>
            <scale>1 1 1</scale>
            <uri>model://ROVER2018/meshes/LMW_col.STL</uri>
          </mesh>
        </geometry>
        <surface>
          <contact>
            <ode/>
          </contact>
          <friction>
            <ode>
              <mu>0</mu>
              <mu2>0</mu2>
            </ode>
          </friction>
        </surface>
      </collision>
      <visual name="LMW_visual">
        <pose>-0.0199999999996418 0.129629204390591 0.56569193394794 0 0 0</pose>
        <material>
          <ambient>1 0 0 1</ambient>
          <diffuse>1 0 0 1</diffuse>
        </material>
        <geometry>
          <mesh>
            <scale>1 1 1</scale>
            <uri>model://ROVER2018/meshes/LMW.STL</uri>
          </mesh>
        </geometry>
      </visual>
    </link>
    <joint name="LMH-LMW" type="revolute">
      <parent>LMH</parent>
      <child>LMW</child>
      <pose>7.97393401308355E-13 -0.00231280370344725 3.47499806707674E-14 0 0 0</pose>
      <axis>
        <xyz>2.00473695615059E-13 -4.94773304452515E-14 -1</xyz>
        <dynamics>
          <damping>0</damping>
          <friction>0.3</friction>
        </dynamics>
        <limit>
          <effort>1</effort>
        </limit>
      </axis>
    </joint>
    <link name="LRW">
      <gravity>1</gravity>
      <self_collide>0</self_collide>
      <pose>-0.552999999995469 0.367099965807295 -0.056146516789596 1.57079632679496 5.53112244015523E-14 4.23969128033834E-15</pose>
      <must_be_base_link>0</must_be_base_link>
      <velocity_decay>
        <linear>0</linear>
        <angular>0</angular>
      </velocity_decay>
      <inertial>
        <mass>11.446866621584</mass>
        <pose>0 0 0 0 0 0</pose>
        <inertia>
          <ixx>0.0935688544901956</ixx>
          <ixy>1.46349791551972E-17</ixy>
          <ixz>2.39909639267274E-16</ixz>
          <iyy>0.0935688544901956</iyy>
          <iyz>3.10641805680222E-15</iyz>
          <izz>0.144062067352231</izz>
        </inertia>
      </inertial>
      <collision name="LRW_collision">
        <pose>0.582999999995473 0.12614651678978 0.567099965807282 0 0 0</pose>
        <geometry>
          <mesh>
            <scale>1 1 1</scale>
            <uri>model://ROVER2018/meshes/LRW_col.STL</uri>
          </mesh>
        </geometry>
        <surface>
          <contact>
            <ode/>
          </contact>
          <friction>
            <ode>
              <mu>0</mu>
              <mu2>0</mu2>
            </ode>
          </friction>
        </surface>
      </collision>
      <visual name="LRW_visual">
        <pose>0.582999999995473 0.12614651678978 0.567099965807282 0 0 0</pose>
        <material>
          <ambient>1 0 0 1</ambient>
          <diffuse>1 0 0 1</diffuse>
        </material>
        <geometry>
          <mesh>
            <scale>1 1 1</scale>
            <uri>model://ROVER2018/meshes/LRW.STL</uri>
          </mesh>
        </geometry>
      </visual>
    </link>
    <joint name="LRH-LRW" type="revolute">
      <parent>LRH</parent>
      <child>LRW</child>
      <pose>0.000199999995868838 -0.00814514743915387 3.1641356201817E-14 0 0 0</pose>
      <axis>
        <xyz>1.68946982008176E-13 -4.94773304452515E-14 -1</xyz>
        <dynamics>
          <damping>0</damping>
          <friction>0.3</friction>
        </dynamics>
        <limit>
          <effort>1</effort>
        </limit>
      </axis>
    </joint>
    <plugin filename="libgz_dc_motor.so" name="RFH-RFW_motor">
      <joint>RFH-RFW</joint>
      <topic>/gazebo/frc/simulator/pwm/6</topic>
      <multiplier>70</multiplier>
    </plugin>
    <plugin filename="libgz_dc_motor.so" name="RMH-RMW_motor">
      <joint>RMH-RMW</joint>
      <topic>/gazebo/frc/simulator/pwm/6</topic>
      <multiplier>70</multiplier>
    </plugin>
    <plugin filename="libgz_dc_motor.so" name="RRH-RRW_motor">
      <joint>RRH-RRW</joint>
      <topic>/gazebo/frc/simulator/pwm/6</topic>
      <multiplier>70</multiplier>
    </plugin>
    <plugin filename="libgz_dc_motor.so" name="LFH-LFW_motor">
      <joint>LFH-LFW</joint>
      <topic>/gazebo/frc/simulator/pwm/3</topic>
      <multiplier>70</multiplier>
    </plugin>
    <plugin filename="libgz_dc_motor.so" name="LMH-LMW_motor">
      <joint>LMH-LMW</joint>
      <topic>/gazebo/frc/simulator/pwm/3</topic>
      <multiplier>70</multiplier>
    </plugin>
    <plugin filename="libgz_dc_motor.so" name="LRH-LRW_motor">
      <joint>LRH-LRW</joint>
      <topic>/gazebo/frc/simulator/pwm/3</topic>
      <multiplier>70</multiplier>
    </plugin>
  </model>
</sdf>

